schematic = {
	size = {x=5, y=6, z=5},
	yslice_prob = {
		{ypos=0, prob=254},
		{ypos=1, prob=254},
		{ypos=2, prob=254},
		{ypos=3, prob=254},
		{ypos=4, prob=254},
		{ypos=5, prob=254},
	},
	data = {
		{name="air", prob=0, param2=0},
		{name="air", prob=0, param2=0},
		{name="air", prob=0, param2=0},
		{name="air", prob=0, param2=0},
		{name="air", prob=0, param2=0},
		{name="air", prob=0, param2=0},
		{name="air", prob=0, param2=0},
		{name="air", prob=0, param2=0},
		{name="air", prob=0, param2=0},
		{name="air", prob=0, param2=0},
		{name="air", prob=0, param2=0},
		{name="air", prob=0, param2=0},
		{name="brewing:clementine", prob=126, param2=1},
		{name="air", prob=0, param2=0},
		{name="air", prob=0, param2=0},
		{name="brewing:clementine", prob=126, param2=1},
		{name="brewing:clementinetree_leaves", prob=254, param2=1},
		{name="brewing:clementinetree_leaves", prob=254, param2=1},
		{name="brewing:clementinetree_leaves", prob=254, param2=1},
		{name="brewing:clementine", prob=126, param2=1},
		{name="air", prob=0, param2=0},
		{name="brewing:clementinetree_leaves", prob=254, param2=1},
		{name="brewing:clementinetree_leaves", prob=254, param2=1},
		{name="brewing:clementinetree_leaves", prob=126, param2=1},
		{name="air", prob=0, param2=0},
		{name="air", prob=0, param2=0},
		{name="air", prob=0, param2=0},
		{name="air", prob=0, param2=0},
		{name="air", prob=0, param2=0},
		{name="air", prob=0, param2=0},
		{name="air", prob=0, param2=0},
		{name="air", prob=0, param2=0},
		{name="air", prob=0, param2=0},
		{name="air", prob=0, param2=0},
		{name="air", prob=0, param2=0},
		{name="air", prob=0, param2=0},
		{name="air", prob=0, param2=0},
		{name="air", prob=0, param2=0},
		{name="air", prob=0, param2=0},
		{name="air", prob=0, param2=0},
		{name="air", prob=0, param2=0},
		{name="brewing:clementinetree_leaves", prob=126, param2=1},
		{name="brewing:clementinetree_leaves", prob=254, param2=1},
		{name="brewing:clementinetree_leaves", prob=254, param2=1},
		{name="air", prob=0, param2=0},
		{name="brewing:clementinetree_leaves", prob=254, param2=1},
		{name="brewing:clementinetree_leaves", prob=254, param2=1},
		{name="brewing:clementinetree_leaves", prob=254, param2=1},
		{name="brewing:clementinetree_leaves", prob=254, param2=1},
		{name="brewing:clementinetree_leaves", prob=254, param2=1},
		{name="brewing:clementinetree_leaves", prob=254, param2=1},
		{name="brewing:clementinetree_leaves", prob=254, param2=1},
		{name="brewing:clementinetree_leaves", prob=254, param2=1},
		{name="brewing:clementinetree_leaves", prob=254, param2=1},
		{name="brewing:clementinetree_leaves", prob=254, param2=1},
		{name="air", prob=0, param2=0},
		{name="air", prob=0, param2=0},
		{name="air", prob=0, param2=0},
		{name="air", prob=0, param2=0},
		{name="air", prob=0, param2=0},
		{name="air", prob=0, param2=0},
		{name="air", prob=0, param2=0},
		{name="brewing:clementinetree_trunk", prob=254, param2=2},
		{name="air", prob=0, param2=0},
		{name="air", prob=0, param2=0},
		{name="air", prob=0, param2=0},
		{name="air", prob=0, param2=0},
		{name="brewing:clementinetree_trunk", prob=254, param2=21},
		{name="air", prob=0, param2=0},
		{name="air", prob=0, param2=0},
		{name="brewing:clementine", prob=254, param2=1},
		{name="brewing:clementinetree_leaves", prob=126, param2=1},
		{name="brewing:clementinetree_trunk", prob=254, param2=20},
		{name="brewing:clementinetree_leaves", prob=254, param2=1},
		{name="brewing:clementine", prob=126, param2=1},
		{name="brewing:clementinetree_leaves", prob=254, param2=1},
		{name="brewing:clementinetree_leaves", prob=254, param2=1},
		{name="brewing:clementinetree_trunk", prob=254, param2=20},
		{name="brewing:clementinetree_leaves", prob=254, param2=1},
		{name="brewing:clementinetree_leaves", prob=254, param2=1},
		{name="brewing:clementinetree_leaves", prob=254, param2=1},
		{name="brewing:clementinetree_leaves", prob=254, param2=1},
		{name="brewing:clementinetree_leaves", prob=254, param2=1},
		{name="brewing:clementinetree_leaves", prob=254, param2=1},
		{name="brewing:clementinetree_leaves", prob=254, param2=1},
		{name="air", prob=0, param2=0},
		{name="brewing:clementinetree_leaves", prob=126, param2=1},
		{name="brewing:clementinetree_leaves", prob=254, param2=1},
		{name="brewing:clementinetree_leaves", prob=126, param2=1},
		{name="air", prob=0, param2=0},
		{name="air", prob=0, param2=0},
		{name="air", prob=0, param2=0},
		{name="air", prob=0, param2=0},
		{name="air", prob=0, param2=0},
		{name="air", prob=0, param2=0},
		{name="air", prob=0, param2=0},
		{name="air", prob=0, param2=0},
		{name="air", prob=0, param2=0},
		{name="air", prob=0, param2=0},
		{name="air", prob=0, param2=0},
		{name="air", prob=0, param2=0},
		{name="brewing:clementinetree_leaves", prob=254, param2=1},
		{name="brewing:clementinetree_leaves", prob=254, param2=1},
		{name="brewing:clementinetree_leaves", prob=126, param2=1},
		{name="air", prob=0, param2=0},
		{name="brewing:clementinetree_leaves", prob=254, param2=1},
		{name="brewing:clementinetree_leaves", prob=254, param2=1},
		{name="brewing:clementinetree_leaves", prob=254, param2=1},
		{name="brewing:clementinetree_leaves", prob=254, param2=1},
		{name="brewing:clementinetree_leaves", prob=254, param2=1},
		{name="brewing:clementinetree_leaves", prob=254, param2=1},
		{name="brewing:clementinetree_leaves", prob=254, param2=1},
		{name="brewing:clementinetree_leaves", prob=254, param2=1},
		{name="brewing:clementinetree_leaves", prob=254, param2=1},
		{name="brewing:clementinetree_leaves", prob=254, param2=1},
		{name="air", prob=0, param2=0},
		{name="air", prob=0, param2=0},
		{name="air", prob=0, param2=0},
		{name="air", prob=0, param2=0},
		{name="air", prob=0, param2=0},
		{name="air", prob=0, param2=0},
		{name="air", prob=0, param2=0},
		{name="air", prob=0, param2=0},
		{name="air", prob=0, param2=0},
		{name="air", prob=0, param2=0},
		{name="air", prob=0, param2=0},
		{name="air", prob=0, param2=0},
		{name="air", prob=0, param2=0},
		{name="air", prob=0, param2=0},
		{name="air", prob=0, param2=0},
		{name="air", prob=0, param2=0},
		{name="air", prob=0, param2=0},
		{name="brewing:clementine", prob=126, param2=1},
		{name="air", prob=0, param2=0},
		{name="air", prob=0, param2=0},
		{name="brewing:clementine", prob=126, param2=1},
		{name="brewing:clementinetree_leaves", prob=254, param2=1},
		{name="brewing:clementinetree_leaves", prob=254, param2=1},
		{name="brewing:clementinetree_leaves", prob=254, param2=1},
		{name="brewing:clementine", prob=126, param2=1},
		{name="air", prob=0, param2=0},
		{name="brewing:clementinetree_leaves", prob=126, param2=1},
		{name="brewing:clementinetree_leaves", prob=254, param2=1},
		{name="brewing:clementinetree_leaves", prob=254, param2=1},
		{name="air", prob=0, param2=0},
		{name="air", prob=0, param2=0},
		{name="air", prob=0, param2=0},
		{name="air", prob=0, param2=0},
		{name="air", prob=0, param2=0},
		{name="air", prob=0, param2=0},
	},
}
